[2021-02-21 00:40:13,083] {taskinstance.py:826} INFO - Dependencies all met for <TaskInstance: docker_ge_quarantine_dag.GE_val_monthlychk 2021-02-20T23:39:53.545677+00:00 [queued]>
[2021-02-21 00:40:13,089] {taskinstance.py:826} INFO - Dependencies all met for <TaskInstance: docker_ge_quarantine_dag.GE_val_monthlychk 2021-02-20T23:39:53.545677+00:00 [queued]>
[2021-02-21 00:40:13,089] {taskinstance.py:1017} INFO - 
--------------------------------------------------------------------------------
[2021-02-21 00:40:13,089] {taskinstance.py:1018} INFO - Starting attempt 1 of 1
[2021-02-21 00:40:13,089] {taskinstance.py:1019} INFO - 
--------------------------------------------------------------------------------
[2021-02-21 00:40:13,097] {taskinstance.py:1038} INFO - Executing <Task(DockerOperator): GE_val_monthlychk> on 2021-02-20T23:39:53.545677+00:00
[2021-02-21 00:40:13,099] {standard_task_runner.py:51} INFO - Started process 17744 to run task
[2021-02-21 00:40:13,106] {standard_task_runner.py:75} INFO - Running: ['airflow', 'tasks', 'run', 'docker_ge_quarantine_dag', 'GE_val_monthlychk', '2021-02-20T23:39:53.545677+00:00', '--job-id', '566', '--pool', 'default_pool', '--raw', '--subdir', 'DAGS_FOLDER/docker_ge_quarantine_dag.py', '--cfg-path', '/var/folders/s2/xy3ssc8j3ks3whp2f_b8708c0000gp/T/tmpzvy_ozh2']
[2021-02-21 00:40:13,108] {standard_task_runner.py:76} INFO - Job 566: Subtask GE_val_monthlychk
[2021-02-21 00:40:13,143] {logging_mixin.py:103} INFO - Running <TaskInstance: docker_ge_quarantine_dag.GE_val_monthlychk 2021-02-20T23:39:53.545677+00:00 [running]> on host 1.0.0.127.in-addr.arpa
[2021-02-21 00:40:13,175] {taskinstance.py:1230} INFO - Exporting the following env vars:
AIRFLOW_CTX_DAG_EMAIL=sara@acloudfrontier.com
AIRFLOW_CTX_DAG_OWNER=sara
AIRFLOW_CTX_DAG_ID=docker_ge_quarantine_dag
AIRFLOW_CTX_TASK_ID=GE_val_monthlychk
AIRFLOW_CTX_EXECUTION_DATE=2021-02-20T23:39:53.545677+00:00
AIRFLOW_CTX_DAG_RUN_ID=manual__2021-02-20T23:39:53.545677+00:00
[2021-02-21 00:40:13,227] {docker.py:224} INFO - Starting docker container from image hacked_ge_image
[2021-02-21 00:40:18,732] {docker.py:263} INFO - Usage: great_expectations [OPTIONS] COMMAND [ARGS]...
Try 'great_expectations --help' for help.

Error: No such command 'great_expectations checkpoint run monthlychk'.
[2021-02-21 00:40:19,586] {taskinstance.py:1396} ERROR - docker container failed: {'Error': None, 'StatusCode': 2}
Traceback (most recent call last):
  File "/Users/sara/p38_demo_env/lib/python3.8/site-packages/airflow/models/taskinstance.py", line 1086, in _run_raw_task
    self._prepare_and_execute_task_with_callbacks(context, task)
  File "/Users/sara/p38_demo_env/lib/python3.8/site-packages/airflow/models/taskinstance.py", line 1260, in _prepare_and_execute_task_with_callbacks
    result = self._execute_task(context, task_copy)
  File "/Users/sara/p38_demo_env/lib/python3.8/site-packages/airflow/models/taskinstance.py", line 1300, in _execute_task
    result = task_copy.execute(context=context)
  File "/Users/sara/p38_demo_env/lib/python3.8/site-packages/airflow/providers/docker/operators/docker.py", line 307, in execute
    return self._run_image()
  File "/Users/sara/p38_demo_env/lib/python3.8/site-packages/airflow/providers/docker/operators/docker.py", line 269, in _run_image
    raise AirflowException('docker container failed: ' + repr(result))
airflow.exceptions.AirflowException: docker container failed: {'Error': None, 'StatusCode': 2}
[2021-02-21 00:40:19,594] {taskinstance.py:1433} INFO - Marking task as FAILED. dag_id=docker_ge_quarantine_dag, task_id=GE_val_monthlychk, execution_date=20210220T233953, start_date=20210220T234013, end_date=20210220T234019
[2021-02-21 00:40:19,635] {local_task_job.py:118} INFO - Task exited with return code 1
