[2021-02-02 10:08:03,391] {taskinstance.py:826} INFO - Dependencies all met for <TaskInstance: ge_snowflake_dag.ge_checkpoint_januarychk 2021-02-01T07:35:16.530226+00:00 [queued]>
[2021-02-02 10:08:03,398] {taskinstance.py:826} INFO - Dependencies all met for <TaskInstance: ge_snowflake_dag.ge_checkpoint_januarychk 2021-02-01T07:35:16.530226+00:00 [queued]>
[2021-02-02 10:08:03,399] {taskinstance.py:1017} INFO - 
--------------------------------------------------------------------------------
[2021-02-02 10:08:03,399] {taskinstance.py:1018} INFO - Starting attempt 1 of 1
[2021-02-02 10:08:03,399] {taskinstance.py:1019} INFO - 
--------------------------------------------------------------------------------
[2021-02-02 10:08:03,406] {taskinstance.py:1038} INFO - Executing <Task(GreatExpectationsOperator): ge_checkpoint_januarychk> on 2021-02-01T07:35:16.530226+00:00
[2021-02-02 10:08:03,409] {standard_task_runner.py:51} INFO - Started process 2069 to run task
[2021-02-02 10:08:03,418] {standard_task_runner.py:75} INFO - Running: ['airflow', 'tasks', 'run', 'ge_snowflake_dag', 'ge_checkpoint_januarychk', '2021-02-01T07:35:16.530226+00:00', '--job-id', '271', '--pool', 'default_pool', '--raw', '--subdir', 'DAGS_FOLDER/ge_snowflake_dag.py', '--cfg-path', '/var/folders/s2/xy3ssc8j3ks3whp2f_b8708c0000gp/T/tmp7zw26y19']
[2021-02-02 10:08:03,419] {standard_task_runner.py:76} INFO - Job 271: Subtask ge_checkpoint_januarychk
[2021-02-02 10:08:03,458] {logging_mixin.py:103} INFO - Running <TaskInstance: ge_snowflake_dag.ge_checkpoint_januarychk 2021-02-01T07:35:16.530226+00:00 [running]> on host 1.0.0.0.0.0.0.0.0.0.0.0.0.0.0.0.0.0.0.0.0.0.0.0.0.0.0.0.0.0.0.0.ip6.arpa
[2021-02-02 10:08:03,496] {taskinstance.py:1230} INFO - Exporting the following env vars:
AIRFLOW_CTX_DAG_EMAIL=sara@acloudfrontier.com
AIRFLOW_CTX_DAG_OWNER=sara
AIRFLOW_CTX_DAG_ID=ge_snowflake_dag
AIRFLOW_CTX_TASK_ID=ge_checkpoint_januarychk
AIRFLOW_CTX_EXECUTION_DATE=2021-02-01T07:35:16.530226+00:00
AIRFLOW_CTX_DAG_RUN_ID=scheduled__2021-02-01T07:35:16.530226+00:00
[2021-02-02 10:08:03,496] {great_expectations.py:97} INFO - Running validation with Great Expectations...
[2021-02-02 10:08:03,515] {data_context.py:755} WARNING - Detected legacy config version (2.0) so will try to use default checkpoint store name.
  Please update your configuration to the new version number 3.0 in order to use the new "Checkpoint Store" feature.  Visit https://docs.greatexpectations.io/en/latest/how_to_guides/migrating_versions.html to learn more about the upgrade process.
[2021-02-02 10:08:03,523] {data_context.py:775} WARNING - Detected legacy config version (2.0) so will try to use default checkpoint store.
  Please update your configuration to the new version number 3.0 in order to use the new "Checkpoint Store" feature.
  Visit https://docs.greatexpectations.io/en/latest/how_to_guides/migrating_versions.html to learn more about the upgrade process.
[2021-02-02 10:08:03,566] {data_context.py:755} WARNING - Detected legacy config version (2.0) so will try to use default checkpoint store name.
  Please update your configuration to the new version number 3.0 in order to use the new "Checkpoint Store" feature.  Visit https://docs.greatexpectations.io/en/latest/how_to_guides/migrating_versions.html to learn more about the upgrade process.
[2021-02-02 10:08:03,644] {taskinstance.py:1396} ERROR - Non-existent checkpoint configuration named "januarychk".

Details: Unable to retrieve object from TupleFilesystemStoreBackend with the following Key: /Users/sara/airflow/dags/snowflake/great_expectations/checkpoints/januarychk.yml
Traceback (most recent call last):
  File "/Users/sara/Dropbox/My Mac (admin’s MacBook Air)/Desktop/demo/great_expectations/great_expectations/data_context/store/tuple_store_backend.py", line 296, in _get
    with open(filepath) as infile:
FileNotFoundError: [Errno 2] No such file or directory: '/Users/sara/airflow/dags/snowflake/great_expectations/checkpoints/januarychk.yml'

During handling of the above exception, another exception occurred:

Traceback (most recent call last):
  File "/Users/sara/Dropbox/My Mac (admin’s MacBook Air)/Desktop/demo/great_expectations/great_expectations/data_context/data_context.py", line 2859, in get_checkpoint
    checkpoint_config: CheckpointConfig = self.checkpoint_store.get(key=key)
  File "/Users/sara/Dropbox/My Mac (admin’s MacBook Air)/Desktop/demo/great_expectations/great_expectations/data_context/store/store.py", line 121, in get
    value = self._store_backend.get(self.key_to_tuple(key))
  File "/Users/sara/Dropbox/My Mac (admin’s MacBook Air)/Desktop/demo/great_expectations/great_expectations/data_context/store/store_backend.py", line 115, in get
    value = self._get(key, **kwargs)
  File "/Users/sara/Dropbox/My Mac (admin’s MacBook Air)/Desktop/demo/great_expectations/great_expectations/data_context/store/tuple_store_backend.py", line 299, in _get
    raise InvalidKeyError(
great_expectations.exceptions.exceptions.InvalidKeyError: Unable to retrieve object from TupleFilesystemStoreBackend with the following Key: /Users/sara/airflow/dags/snowflake/great_expectations/checkpoints/januarychk.yml

During handling of the above exception, another exception occurred:

Traceback (most recent call last):
  File "/Users/sara/p38_demo_env/lib/python3.8/site-packages/airflow/models/taskinstance.py", line 1086, in _run_raw_task
    self._prepare_and_execute_task_with_callbacks(context, task)
  File "/Users/sara/p38_demo_env/lib/python3.8/site-packages/airflow/models/taskinstance.py", line 1260, in _prepare_and_execute_task_with_callbacks
    result = self._execute_task(context, task_copy)
  File "/Users/sara/p38_demo_env/lib/python3.8/site-packages/airflow/models/taskinstance.py", line 1300, in _execute_task
    result = task_copy.execute(context=context)
  File "/Users/sara/p38_demo_env/lib/python3.8/site-packages/great_expectations_provider/operators/great_expectations.py", line 107, in execute
    checkpoint = self.data_context.get_checkpoint(self.checkpoint_name)
  File "/Users/sara/Dropbox/My Mac (admin’s MacBook Air)/Desktop/demo/great_expectations/great_expectations/data_context/data_context.py", line 2861, in get_checkpoint
    raise ge_exceptions.CheckpointNotFoundError(
great_expectations.exceptions.exceptions.CheckpointNotFoundError: Non-existent checkpoint configuration named "januarychk".

Details: Unable to retrieve object from TupleFilesystemStoreBackend with the following Key: /Users/sara/airflow/dags/snowflake/great_expectations/checkpoints/januarychk.yml
[2021-02-02 10:08:03,661] {taskinstance.py:1433} INFO - Marking task as FAILED. dag_id=ge_snowflake_dag, task_id=ge_checkpoint_januarychk, execution_date=20210201T073516, start_date=20210202T090803, end_date=20210202T090803
[2021-02-02 10:08:03,721] {local_task_job.py:118} INFO - Task exited with return code 1
