[2021-02-02 11:51:57,980] {taskinstance.py:826} INFO - Dependencies all met for <TaskInstance: ge_quarantine_df_dag.import_to_quarantine_data 2021-02-02T10:51:26.978720+00:00 [queued]>
[2021-02-02 11:51:57,990] {taskinstance.py:826} INFO - Dependencies all met for <TaskInstance: ge_quarantine_df_dag.import_to_quarantine_data 2021-02-02T10:51:26.978720+00:00 [queued]>
[2021-02-02 11:51:57,990] {taskinstance.py:1017} INFO - 
--------------------------------------------------------------------------------
[2021-02-02 11:51:57,990] {taskinstance.py:1018} INFO - Starting attempt 1 of 1
[2021-02-02 11:51:57,990] {taskinstance.py:1019} INFO - 
--------------------------------------------------------------------------------
[2021-02-02 11:51:57,999] {taskinstance.py:1038} INFO - Executing <Task(SnowflakeOperator): import_to_quarantine_data> on 2021-02-02T10:51:26.978720+00:00
[2021-02-02 11:51:58,003] {standard_task_runner.py:51} INFO - Started process 10130 to run task
[2021-02-02 11:51:58,014] {standard_task_runner.py:75} INFO - Running: ['airflow', 'tasks', 'run', 'ge_quarantine_df_dag', 'import_to_quarantine_data', '2021-02-02T10:51:26.978720+00:00', '--job-id', '289', '--pool', 'default_pool', '--raw', '--subdir', 'DAGS_FOLDER/ge_quarantine_df_dag.py', '--cfg-path', '/var/folders/s2/xy3ssc8j3ks3whp2f_b8708c0000gp/T/tmps7pwxayf']
[2021-02-02 11:51:58,019] {standard_task_runner.py:76} INFO - Job 289: Subtask import_to_quarantine_data
[2021-02-02 11:51:58,075] {logging_mixin.py:103} INFO - Running <TaskInstance: ge_quarantine_df_dag.import_to_quarantine_data 2021-02-02T10:51:26.978720+00:00 [running]> on host 1.0.0.127.in-addr.arpa
[2021-02-02 11:51:58,122] {taskinstance.py:1230} INFO - Exporting the following env vars:
AIRFLOW_CTX_DAG_EMAIL=sara@acloudfrontier.com
AIRFLOW_CTX_DAG_OWNER=sara
AIRFLOW_CTX_DAG_ID=ge_quarantine_df_dag
AIRFLOW_CTX_TASK_ID=import_to_quarantine_data
AIRFLOW_CTX_EXECUTION_DATE=2021-02-02T10:51:26.978720+00:00
AIRFLOW_CTX_DAG_RUN_ID=manual__2021-02-02T10:51:26.978720+00:00
[2021-02-02 11:51:58,123] {snowflake.py:119} INFO - Executing: ['alter table QUARANTINE_DATA add column error integer;', 'insert into  QUARANTINE_DATA select * from RAW_MONTHLY_DATA where error=1;', 'alter table QUARANTINE_DATA drop column error;']
[2021-02-02 11:51:58,135] {base.py:65} INFO - Using connection to: id: SNOWFLAKE_QUARANTINE_DEMO. Host: dp13486.eu-west-1.snowflakecomputing.com, Port: None, Schema: PUBLIC, Login: SARA, Password: XXXXXXXX, extra: XXXXXXXX
[2021-02-02 11:51:58,140] {connection.py:215} INFO - Snowflake Connector for Python Version: 2.3.9, Python Version: 3.8.6, Platform: macOS-10.16-x86_64-i386-64bit
[2021-02-02 11:51:58,142] {connection.py:768} INFO - This connection is in OCSP Fail Open Mode. TLS Certificates would be checked for validity and revocation status. Any other Certificate Revocation related exceptions or OCSP Responder failures would be disregarded in favor of connectivity.
[2021-02-02 11:51:58,142] {connection.py:784} INFO - Setting use_openssl_only mode to False
[2021-02-02 11:51:59,543] {cursor.py:537} INFO - query: [ALTER SESSION SET autocommit=True]
[2021-02-02 11:51:59,677] {cursor.py:560} INFO - query execution done
[2021-02-02 11:51:59,679] {dbapi.py:180} INFO - Running statement: alter table QUARANTINE_DATA add column error integer;, parameters: None
[2021-02-02 11:51:59,679] {cursor.py:537} INFO - query: [alter table QUARANTINE_DATA add column error integer;]
[2021-02-02 11:51:59,976] {cursor.py:560} INFO - query execution done
[2021-02-02 11:51:59,977] {dbapi.py:186} INFO - Rows affected: 1
[2021-02-02 11:51:59,978] {dbapi.py:180} INFO - Running statement: insert into  QUARANTINE_DATA select * from RAW_MONTHLY_DATA where error=1;, parameters: None
[2021-02-02 11:51:59,979] {cursor.py:537} INFO - query: [insert into  QUARANTINE_DATA select * from RAW_MONTHLY_DATA where error=1;]
[2021-02-02 11:52:00,253] {cursor.py:560} INFO - query execution done
[2021-02-02 11:52:00,278] {connection.py:438} INFO - closed
[2021-02-02 11:52:00,358] {connection.py:441} INFO - No async queries seem to be running, deleting session
[2021-02-02 11:52:00,488] {taskinstance.py:1396} ERROR - 002003 (42S02): 019a050c-00e1-dd20-0000-a0110004e49e: SQL compilation error:
Object 'RAW_MONTHLY_DATA' does not exist or not authorized.
Traceback (most recent call last):
  File "/Users/sara/p38_demo_env/lib/python3.8/site-packages/airflow/models/taskinstance.py", line 1086, in _run_raw_task
    self._prepare_and_execute_task_with_callbacks(context, task)
  File "/Users/sara/p38_demo_env/lib/python3.8/site-packages/airflow/models/taskinstance.py", line 1260, in _prepare_and_execute_task_with_callbacks
    result = self._execute_task(context, task_copy)
  File "/Users/sara/p38_demo_env/lib/python3.8/site-packages/airflow/models/taskinstance.py", line 1300, in _execute_task
    result = task_copy.execute(context=context)
  File "/Users/sara/p38_demo_env/lib/python3.8/site-packages/airflow/providers/snowflake/operators/snowflake.py", line 121, in execute
    hook.run(self.sql, autocommit=self.autocommit, parameters=self.parameters)
  File "/Users/sara/p38_demo_env/lib/python3.8/site-packages/airflow/hooks/dbapi.py", line 184, in run
    cur.execute(sql_statement)
  File "/Users/sara/p38_demo_env/lib/python3.8/site-packages/snowflake/connector/cursor.py", line 612, in execute
    Error.errorhandler_wrapper(self.connection, self,
  File "/Users/sara/p38_demo_env/lib/python3.8/site-packages/snowflake/connector/errors.py", line 224, in errorhandler_wrapper
    cursor.errorhandler(connection, cursor, error_class, error_value)
  File "/Users/sara/p38_demo_env/lib/python3.8/site-packages/snowflake/connector/errors.py", line 179, in default_errorhandler
    raise error_class(
snowflake.connector.errors.ProgrammingError: 002003 (42S02): 019a050c-00e1-dd20-0000-a0110004e49e: SQL compilation error:
Object 'RAW_MONTHLY_DATA' does not exist or not authorized.
[2021-02-02 11:52:00,491] {taskinstance.py:1433} INFO - Marking task as FAILED. dag_id=ge_quarantine_df_dag, task_id=import_to_quarantine_data, execution_date=20210202T105126, start_date=20210202T105157, end_date=20210202T105200
[2021-02-02 11:52:00,549] {local_task_job.py:118} INFO - Task exited with return code 1
