[2021-01-22 11:47:09,528] {taskinstance.py:826} INFO - Dependencies all met for <TaskInstance: connection_snowflake.snowflake_create 2021-01-22T10:41:58.666298+00:00 [queued]>
[2021-01-22 11:47:09,536] {taskinstance.py:826} INFO - Dependencies all met for <TaskInstance: connection_snowflake.snowflake_create 2021-01-22T10:41:58.666298+00:00 [queued]>
[2021-01-22 11:47:09,536] {taskinstance.py:1017} INFO - 
--------------------------------------------------------------------------------
[2021-01-22 11:47:09,536] {taskinstance.py:1018} INFO - Starting attempt 2 of 2
[2021-01-22 11:47:09,536] {taskinstance.py:1019} INFO - 
--------------------------------------------------------------------------------
[2021-01-22 11:47:09,545] {taskinstance.py:1038} INFO - Executing <Task(SnowflakeOperator): snowflake_create> on 2021-01-22T10:41:58.666298+00:00
[2021-01-22 11:47:09,549] {standard_task_runner.py:51} INFO - Started process 3551 to run task
[2021-01-22 11:47:09,559] {standard_task_runner.py:75} INFO - Running: ['airflow', 'tasks', 'run', 'connection_snowflake', 'snowflake_create', '2021-01-22T10:41:58.666298+00:00', '--job-id', '20', '--pool', 'default_pool', '--raw', '--subdir', 'DAGS_FOLDER/connection_snowflake_dag.py', '--cfg-path', '/var/folders/s2/xy3ssc8j3ks3whp2f_b8708c0000gp/T/tmpwh0x8aws']
[2021-01-22 11:47:09,561] {standard_task_runner.py:76} INFO - Job 20: Subtask snowflake_create
[2021-01-22 11:47:09,602] {logging_mixin.py:103} INFO - Running <TaskInstance: connection_snowflake.snowflake_create 2021-01-22T10:41:58.666298+00:00 [running]> on host admins-air.home
[2021-01-22 11:47:09,632] {taskinstance.py:1230} INFO - Exporting the following env vars:
AIRFLOW_CTX_DAG_EMAIL=sara@acloudfrontier.com
AIRFLOW_CTX_DAG_OWNER=sara
AIRFLOW_CTX_DAG_ID=connection_snowflake
AIRFLOW_CTX_TASK_ID=snowflake_create
AIRFLOW_CTX_EXECUTION_DATE=2021-01-22T10:41:58.666298+00:00
AIRFLOW_CTX_DAG_RUN_ID=manual__2021-01-22T10:41:58.666298+00:00
[2021-01-22 11:47:09,633] {snowflake.py:119} INFO - Executing: ['create table public.test_employee (id number, name string);', 'insert into public.test_employee values(1, “Sam”),(2, “Andy”),(3, “Gill”);']
[2021-01-22 11:47:09,641] {connection.py:337} ERROR - Expecting property name enclosed in double quotes: line 2 column 9 (char 12)
Traceback (most recent call last):
  File "/Users/sara/p38env_airflow/lib/python3.8/site-packages/airflow/models/connection.py", line 335, in extra_dejson
    obj = json.loads(self.extra)
  File "/Library/Frameworks/Python.framework/Versions/3.8/lib/python3.8/json/__init__.py", line 357, in loads
    return _default_decoder.decode(s)
  File "/Library/Frameworks/Python.framework/Versions/3.8/lib/python3.8/json/decoder.py", line 337, in decode
    obj, end = self.raw_decode(s, idx=_w(s, 0).end())
  File "/Library/Frameworks/Python.framework/Versions/3.8/lib/python3.8/json/decoder.py", line 353, in raw_decode
    obj, end = self.scan_once(s, idx)
json.decoder.JSONDecodeError: Expecting property name enclosed in double quotes: line 2 column 9 (char 12)
[2021-01-22 11:47:09,646] {connection.py:338} ERROR - Failed parsing the json for conn_id snowflake_conn
[2021-01-22 11:47:09,647] {base.py:65} INFO - Using connection to: id: snowflake_conn. Host: dp13486.eu-west-1.snowflakecomputing.com, Port: None, Schema: PUBLIC, Login: SARA, Password: XXXXXXXX, extra: None
[2021-01-22 11:47:09,648] {connection.py:337} ERROR - Expecting property name enclosed in double quotes: line 2 column 9 (char 12)
Traceback (most recent call last):
  File "/Users/sara/p38env_airflow/lib/python3.8/site-packages/airflow/models/connection.py", line 335, in extra_dejson
    obj = json.loads(self.extra)
  File "/Library/Frameworks/Python.framework/Versions/3.8/lib/python3.8/json/__init__.py", line 357, in loads
    return _default_decoder.decode(s)
  File "/Library/Frameworks/Python.framework/Versions/3.8/lib/python3.8/json/decoder.py", line 337, in decode
    obj, end = self.raw_decode(s, idx=_w(s, 0).end())
  File "/Library/Frameworks/Python.framework/Versions/3.8/lib/python3.8/json/decoder.py", line 353, in raw_decode
    obj, end = self.scan_once(s, idx)
json.decoder.JSONDecodeError: Expecting property name enclosed in double quotes: line 2 column 9 (char 12)
[2021-01-22 11:47:09,648] {connection.py:338} ERROR - Failed parsing the json for conn_id snowflake_conn
[2021-01-22 11:47:09,650] {connection.py:337} ERROR - Expecting property name enclosed in double quotes: line 2 column 9 (char 12)
Traceback (most recent call last):
  File "/Users/sara/p38env_airflow/lib/python3.8/site-packages/airflow/models/connection.py", line 335, in extra_dejson
    obj = json.loads(self.extra)
  File "/Library/Frameworks/Python.framework/Versions/3.8/lib/python3.8/json/__init__.py", line 357, in loads
    return _default_decoder.decode(s)
  File "/Library/Frameworks/Python.framework/Versions/3.8/lib/python3.8/json/decoder.py", line 337, in decode
    obj, end = self.raw_decode(s, idx=_w(s, 0).end())
  File "/Library/Frameworks/Python.framework/Versions/3.8/lib/python3.8/json/decoder.py", line 353, in raw_decode
    obj, end = self.scan_once(s, idx)
json.decoder.JSONDecodeError: Expecting property name enclosed in double quotes: line 2 column 9 (char 12)
[2021-01-22 11:47:09,651] {connection.py:338} ERROR - Failed parsing the json for conn_id snowflake_conn
[2021-01-22 11:47:09,651] {connection.py:337} ERROR - Expecting property name enclosed in double quotes: line 2 column 9 (char 12)
Traceback (most recent call last):
  File "/Users/sara/p38env_airflow/lib/python3.8/site-packages/airflow/models/connection.py", line 335, in extra_dejson
    obj = json.loads(self.extra)
  File "/Library/Frameworks/Python.framework/Versions/3.8/lib/python3.8/json/__init__.py", line 357, in loads
    return _default_decoder.decode(s)
  File "/Library/Frameworks/Python.framework/Versions/3.8/lib/python3.8/json/decoder.py", line 337, in decode
    obj, end = self.raw_decode(s, idx=_w(s, 0).end())
  File "/Library/Frameworks/Python.framework/Versions/3.8/lib/python3.8/json/decoder.py", line 353, in raw_decode
    obj, end = self.scan_once(s, idx)
json.decoder.JSONDecodeError: Expecting property name enclosed in double quotes: line 2 column 9 (char 12)
[2021-01-22 11:47:09,652] {connection.py:338} ERROR - Failed parsing the json for conn_id snowflake_conn
[2021-01-22 11:47:09,653] {connection.py:337} ERROR - Expecting property name enclosed in double quotes: line 2 column 9 (char 12)
Traceback (most recent call last):
  File "/Users/sara/p38env_airflow/lib/python3.8/site-packages/airflow/models/connection.py", line 335, in extra_dejson
    obj = json.loads(self.extra)
  File "/Library/Frameworks/Python.framework/Versions/3.8/lib/python3.8/json/__init__.py", line 357, in loads
    return _default_decoder.decode(s)
  File "/Library/Frameworks/Python.framework/Versions/3.8/lib/python3.8/json/decoder.py", line 337, in decode
    obj, end = self.raw_decode(s, idx=_w(s, 0).end())
  File "/Library/Frameworks/Python.framework/Versions/3.8/lib/python3.8/json/decoder.py", line 353, in raw_decode
    obj, end = self.scan_once(s, idx)
json.decoder.JSONDecodeError: Expecting property name enclosed in double quotes: line 2 column 9 (char 12)
[2021-01-22 11:47:09,653] {connection.py:338} ERROR - Failed parsing the json for conn_id snowflake_conn
[2021-01-22 11:47:09,654] {connection.py:337} ERROR - Expecting property name enclosed in double quotes: line 2 column 9 (char 12)
Traceback (most recent call last):
  File "/Users/sara/p38env_airflow/lib/python3.8/site-packages/airflow/models/connection.py", line 335, in extra_dejson
    obj = json.loads(self.extra)
  File "/Library/Frameworks/Python.framework/Versions/3.8/lib/python3.8/json/__init__.py", line 357, in loads
    return _default_decoder.decode(s)
  File "/Library/Frameworks/Python.framework/Versions/3.8/lib/python3.8/json/decoder.py", line 337, in decode
    obj, end = self.raw_decode(s, idx=_w(s, 0).end())
  File "/Library/Frameworks/Python.framework/Versions/3.8/lib/python3.8/json/decoder.py", line 353, in raw_decode
    obj, end = self.scan_once(s, idx)
json.decoder.JSONDecodeError: Expecting property name enclosed in double quotes: line 2 column 9 (char 12)
[2021-01-22 11:47:09,655] {connection.py:338} ERROR - Failed parsing the json for conn_id snowflake_conn
[2021-01-22 11:47:09,655] {connection.py:337} ERROR - Expecting property name enclosed in double quotes: line 2 column 9 (char 12)
Traceback (most recent call last):
  File "/Users/sara/p38env_airflow/lib/python3.8/site-packages/airflow/models/connection.py", line 335, in extra_dejson
    obj = json.loads(self.extra)
  File "/Library/Frameworks/Python.framework/Versions/3.8/lib/python3.8/json/__init__.py", line 357, in loads
    return _default_decoder.decode(s)
  File "/Library/Frameworks/Python.framework/Versions/3.8/lib/python3.8/json/decoder.py", line 337, in decode
    obj, end = self.raw_decode(s, idx=_w(s, 0).end())
  File "/Library/Frameworks/Python.framework/Versions/3.8/lib/python3.8/json/decoder.py", line 353, in raw_decode
    obj, end = self.scan_once(s, idx)
json.decoder.JSONDecodeError: Expecting property name enclosed in double quotes: line 2 column 9 (char 12)
[2021-01-22 11:47:09,656] {connection.py:338} ERROR - Failed parsing the json for conn_id snowflake_conn
[2021-01-22 11:47:09,657] {connection.py:337} ERROR - Expecting property name enclosed in double quotes: line 2 column 9 (char 12)
Traceback (most recent call last):
  File "/Users/sara/p38env_airflow/lib/python3.8/site-packages/airflow/models/connection.py", line 335, in extra_dejson
    obj = json.loads(self.extra)
  File "/Library/Frameworks/Python.framework/Versions/3.8/lib/python3.8/json/__init__.py", line 357, in loads
    return _default_decoder.decode(s)
  File "/Library/Frameworks/Python.framework/Versions/3.8/lib/python3.8/json/decoder.py", line 337, in decode
    obj, end = self.raw_decode(s, idx=_w(s, 0).end())
  File "/Library/Frameworks/Python.framework/Versions/3.8/lib/python3.8/json/decoder.py", line 353, in raw_decode
    obj, end = self.scan_once(s, idx)
json.decoder.JSONDecodeError: Expecting property name enclosed in double quotes: line 2 column 9 (char 12)
[2021-01-22 11:47:09,657] {connection.py:338} ERROR - Failed parsing the json for conn_id snowflake_conn
[2021-01-22 11:47:09,658] {connection.py:337} ERROR - Expecting property name enclosed in double quotes: line 2 column 9 (char 12)
Traceback (most recent call last):
  File "/Users/sara/p38env_airflow/lib/python3.8/site-packages/airflow/models/connection.py", line 335, in extra_dejson
    obj = json.loads(self.extra)
  File "/Library/Frameworks/Python.framework/Versions/3.8/lib/python3.8/json/__init__.py", line 357, in loads
    return _default_decoder.decode(s)
  File "/Library/Frameworks/Python.framework/Versions/3.8/lib/python3.8/json/decoder.py", line 337, in decode
    obj, end = self.raw_decode(s, idx=_w(s, 0).end())
  File "/Library/Frameworks/Python.framework/Versions/3.8/lib/python3.8/json/decoder.py", line 353, in raw_decode
    obj, end = self.scan_once(s, idx)
json.decoder.JSONDecodeError: Expecting property name enclosed in double quotes: line 2 column 9 (char 12)
[2021-01-22 11:47:09,659] {connection.py:338} ERROR - Failed parsing the json for conn_id snowflake_conn
[2021-01-22 11:47:09,660] {connection.py:215} INFO - Snowflake Connector for Python Version: 2.3.8, Python Version: 3.8.6, Platform: macOS-10.16-x86_64-i386-64bit
[2021-01-22 11:47:09,683] {taskinstance.py:1396} ERROR - 251001: None: Account must be specified
Traceback (most recent call last):
  File "/Users/sara/p38env_airflow/lib/python3.8/site-packages/airflow/models/taskinstance.py", line 1086, in _run_raw_task
    self._prepare_and_execute_task_with_callbacks(context, task)
  File "/Users/sara/p38env_airflow/lib/python3.8/site-packages/airflow/models/taskinstance.py", line 1260, in _prepare_and_execute_task_with_callbacks
    result = self._execute_task(context, task_copy)
  File "/Users/sara/p38env_airflow/lib/python3.8/site-packages/airflow/models/taskinstance.py", line 1300, in _execute_task
    result = task_copy.execute(context=context)
  File "/Users/sara/p38env_airflow/lib/python3.8/site-packages/airflow/providers/snowflake/operators/snowflake.py", line 121, in execute
    hook.run(self.sql, autocommit=self.autocommit, parameters=self.parameters)
  File "/Users/sara/p38env_airflow/lib/python3.8/site-packages/airflow/hooks/dbapi.py", line 173, in run
    with closing(self.get_conn()) as conn:
  File "/Users/sara/p38env_airflow/lib/python3.8/site-packages/airflow/providers/snowflake/hooks/snowflake.py", line 122, in get_conn
    conn = connector.connect(**conn_config)
  File "/Users/sara/p38env_airflow/lib/python3.8/site-packages/snowflake/connector/__init__.py", line 52, in Connect
    return SnowflakeConnection(**kwargs)
  File "/Users/sara/p38env_airflow/lib/python3.8/site-packages/snowflake/connector/connection.py", line 228, in __init__
    self.connect(**kwargs)
  File "/Users/sara/p38env_airflow/lib/python3.8/site-packages/snowflake/connector/connection.py", line 419, in connect
    self.__config(**kwargs)
  File "/Users/sara/p38env_airflow/lib/python3.8/site-packages/snowflake/connector/connection.py", line 758, in __config
    Error.errorhandler_wrapper(
  File "/Users/sara/p38env_airflow/lib/python3.8/site-packages/snowflake/connector/errors.py", line 227, in errorhandler_wrapper
    connection.errorhandler(connection, cursor, error_class, error_value)
  File "/Users/sara/p38env_airflow/lib/python3.8/site-packages/snowflake/connector/errors.py", line 179, in default_errorhandler
    raise error_class(
snowflake.connector.errors.ProgrammingError: 251001: None: Account must be specified
[2021-01-22 11:47:09,685] {taskinstance.py:1433} INFO - Marking task as FAILED. dag_id=connection_snowflake, task_id=snowflake_create, execution_date=20210122T104158, start_date=20210122T104709, end_date=20210122T104709
[2021-01-22 11:47:09,742] {local_task_job.py:118} INFO - Task exited with return code 1
