[2021-02-08 08:27:32,395] {taskinstance.py:826} INFO - Dependencies all met for <TaskInstance: ge_quarantine_df_dag.import_invalid_records 2021-02-06T11:39:51.071972+00:00 [queued]>
[2021-02-08 08:27:32,402] {taskinstance.py:826} INFO - Dependencies all met for <TaskInstance: ge_quarantine_df_dag.import_invalid_records 2021-02-06T11:39:51.071972+00:00 [queued]>
[2021-02-08 08:27:32,402] {taskinstance.py:1017} INFO - 
--------------------------------------------------------------------------------
[2021-02-08 08:27:32,402] {taskinstance.py:1018} INFO - Starting attempt 1 of 1
[2021-02-08 08:27:32,402] {taskinstance.py:1019} INFO - 
--------------------------------------------------------------------------------
[2021-02-08 08:27:32,408] {taskinstance.py:1038} INFO - Executing <Task(SnowflakeOperator): import_invalid_records> on 2021-02-06T11:39:51.071972+00:00
[2021-02-08 08:27:32,411] {standard_task_runner.py:51} INFO - Started process 1094 to run task
[2021-02-08 08:27:32,418] {standard_task_runner.py:75} INFO - Running: ['airflow', 'tasks', 'run', 'ge_quarantine_df_dag', 'import_invalid_records', '2021-02-06T11:39:51.071972+00:00', '--job-id', '361', '--pool', 'default_pool', '--raw', '--subdir', 'DAGS_FOLDER/ge_quarantine_df_dag.py', '--cfg-path', '/var/folders/s2/xy3ssc8j3ks3whp2f_b8708c0000gp/T/tmp7lsxltu_']
[2021-02-08 08:27:32,422] {standard_task_runner.py:76} INFO - Job 361: Subtask import_invalid_records
[2021-02-08 08:27:32,454] {logging_mixin.py:103} INFO - Running <TaskInstance: ge_quarantine_df_dag.import_invalid_records 2021-02-06T11:39:51.071972+00:00 [running]> on host 1.0.0.0.0.0.0.0.0.0.0.0.0.0.0.0.0.0.0.0.0.0.0.0.0.0.0.0.0.0.0.0.ip6.arpa
[2021-02-08 08:27:32,490] {taskinstance.py:1230} INFO - Exporting the following env vars:
AIRFLOW_CTX_DAG_EMAIL=sara@acloudfrontier.com
AIRFLOW_CTX_DAG_OWNER=sara
AIRFLOW_CTX_DAG_ID=ge_quarantine_df_dag
AIRFLOW_CTX_TASK_ID=import_invalid_records
AIRFLOW_CTX_EXECUTION_DATE=2021-02-06T11:39:51.071972+00:00
AIRFLOW_CTX_DAG_RUN_ID=scheduled__2021-02-06T11:39:51.071972+00:00
[2021-02-08 08:27:32,491] {snowflake.py:119} INFO - Executing: ['alter table QUARANTINE_DATA add column error integer;', 'insert into  QUARANTINE_DATA select * from RAW_MONTHLY_TAXI where error=1;', 'alter table QUARANTINE_DATA drop column error;']
[2021-02-08 08:27:32,501] {base.py:65} INFO - Using connection to: id: SNOWFLAKE_QUARANTINE_DEMO. Host: dp13486.eu-west-1.snowflakecomputing.com, Port: None, Schema: PUBLIC, Login: SARA, Password: XXXXXXXX, extra: XXXXXXXX
[2021-02-08 08:27:32,504] {connection.py:215} INFO - Snowflake Connector for Python Version: 2.3.9, Python Version: 3.8.6, Platform: macOS-10.16-x86_64-i386-64bit
[2021-02-08 08:27:32,505] {connection.py:768} INFO - This connection is in OCSP Fail Open Mode. TLS Certificates would be checked for validity and revocation status. Any other Certificate Revocation related exceptions or OCSP Responder failures would be disregarded in favor of connectivity.
[2021-02-08 08:27:32,506] {connection.py:784} INFO - Setting use_openssl_only mode to False
[2021-02-08 08:27:33,762] {cursor.py:537} INFO - query: [ALTER SESSION SET autocommit=True]
[2021-02-08 08:27:33,959] {cursor.py:560} INFO - query execution done
[2021-02-08 08:27:33,960] {dbapi.py:180} INFO - Running statement: alter table QUARANTINE_DATA add column error integer;, parameters: None
[2021-02-08 08:27:33,961] {cursor.py:537} INFO - query: [alter table QUARANTINE_DATA add column error integer;]
[2021-02-08 08:27:34,273] {cursor.py:560} INFO - query execution done
[2021-02-08 08:27:34,274] {dbapi.py:186} INFO - Rows affected: 1
[2021-02-08 08:27:34,274] {dbapi.py:180} INFO - Running statement: insert into  QUARANTINE_DATA select * from RAW_MONTHLY_TAXI where error=1;, parameters: None
[2021-02-08 08:27:34,275] {cursor.py:537} INFO - query: [insert into  QUARANTINE_DATA select * from RAW_MONTHLY_TAXI where error=1;]
[2021-02-08 08:27:34,884] {cursor.py:560} INFO - query execution done
[2021-02-08 08:27:34,885] {dbapi.py:186} INFO - Rows affected: 1579
[2021-02-08 08:27:34,886] {dbapi.py:180} INFO - Running statement: alter table QUARANTINE_DATA drop column error;, parameters: None
[2021-02-08 08:27:34,887] {cursor.py:537} INFO - query: [alter table QUARANTINE_DATA drop column error;]
[2021-02-08 08:27:35,140] {cursor.py:560} INFO - query execution done
[2021-02-08 08:27:35,141] {dbapi.py:186} INFO - Rows affected: 1
[2021-02-08 08:27:35,142] {connection.py:438} INFO - closed
[2021-02-08 08:27:35,224] {connection.py:441} INFO - No async queries seem to be running, deleting session
[2021-02-08 08:27:35,350] {taskinstance.py:1135} INFO - Marking task as SUCCESS. dag_id=ge_quarantine_df_dag, task_id=import_invalid_records, execution_date=20210206T113951, start_date=20210208T072732, end_date=20210208T072735
[2021-02-08 08:27:35,368] {taskinstance.py:1195} INFO - 0 downstream tasks scheduled from follow-on schedule check
[2021-02-08 08:27:35,417] {local_task_job.py:118} INFO - Task exited with return code 0
