[2021-01-21 13:04:41,593] {taskinstance.py:826} INFO - Dependencies all met for <TaskInstance: ge_local_dag.ge_val_03 2021-01-21T12:03:51.043362+00:00 [queued]>
[2021-01-21 13:04:41,600] {taskinstance.py:826} INFO - Dependencies all met for <TaskInstance: ge_local_dag.ge_val_03 2021-01-21T12:03:51.043362+00:00 [queued]>
[2021-01-21 13:04:41,600] {taskinstance.py:1017} INFO - 
--------------------------------------------------------------------------------
[2021-01-21 13:04:41,600] {taskinstance.py:1018} INFO - Starting attempt 1 of 1
[2021-01-21 13:04:41,600] {taskinstance.py:1019} INFO - 
--------------------------------------------------------------------------------
[2021-01-21 13:04:41,608] {taskinstance.py:1038} INFO - Executing <Task(GreatExpectationsOperator): ge_val_03> on 2021-01-21T12:03:51.043362+00:00
[2021-01-21 13:04:41,611] {standard_task_runner.py:51} INFO - Started process 16696 to run task
[2021-01-21 13:04:41,621] {standard_task_runner.py:75} INFO - Running: ['airflow', 'tasks', 'run', 'ge_local_dag', 'ge_val_03', '2021-01-21T12:03:51.043362+00:00', '--job-id', '8', '--pool', 'default_pool', '--raw', '--subdir', 'DAGS_FOLDER/ge_local_dag.py', '--cfg-path', '/var/folders/s2/xy3ssc8j3ks3whp2f_b8708c0000gp/T/tmph51hm03u']
[2021-01-21 13:04:41,622] {standard_task_runner.py:76} INFO - Job 8: Subtask ge_val_03
[2021-01-21 13:04:41,658] {logging_mixin.py:103} INFO - Running <TaskInstance: ge_local_dag.ge_val_03 2021-01-21T12:03:51.043362+00:00 [running]> on host admins-air.home
[2021-01-21 13:04:41,686] {taskinstance.py:1230} INFO - Exporting the following env vars:
AIRFLOW_CTX_DAG_EMAIL=sara@acloudfrontier.com
AIRFLOW_CTX_DAG_OWNER=sara
AIRFLOW_CTX_DAG_ID=ge_local_dag
AIRFLOW_CTX_TASK_ID=ge_val_03
AIRFLOW_CTX_EXECUTION_DATE=2021-01-21T12:03:51.043362+00:00
AIRFLOW_CTX_DAG_RUN_ID=manual__2021-01-21T12:03:51.043362+00:00
[2021-01-21 13:04:41,687] {great_expectations.py:94} INFO - Running validation with Great Expectations...
[2021-01-21 13:04:41,791] {data_context.py:1215} INFO - Setting run_name to: 20210121T120441.791043Z
[2021-01-21 13:04:41,795] {data_asset.py:636} INFO - 	14 expectation(s) included in expectation_suite.
[2021-01-21 13:04:42,798] {taskinstance.py:1396} ERROR - Validation with Great Expectations failed.
Traceback (most recent call last):
  File "/Users/sara/p38env_airflow/lib/python3.8/site-packages/airflow/models/taskinstance.py", line 1086, in _run_raw_task
    self._prepare_and_execute_task_with_callbacks(context, task)
  File "/Users/sara/p38env_airflow/lib/python3.8/site-packages/airflow/models/taskinstance.py", line 1260, in _prepare_and_execute_task_with_callbacks
    result = self._execute_task(context, task_copy)
  File "/Users/sara/p38env_airflow/lib/python3.8/site-packages/airflow/models/taskinstance.py", line 1300, in _execute_task
    result = task_copy.execute(context=context)
  File "/Users/sara/p38env_airflow/lib/python3.8/site-packages/great_expectations_provider/operators/great_expectations.py", line 130, in execute
    raise AirflowException("Validation with Great Expectations failed.")
airflow.exceptions.AirflowException: Validation with Great Expectations failed.
[2021-01-21 13:04:42,800] {taskinstance.py:1433} INFO - Marking task as FAILED. dag_id=ge_local_dag, task_id=ge_val_03, execution_date=20210121T120351, start_date=20210121T120441, end_date=20210121T120442
[2021-01-21 13:04:42,841] {local_task_job.py:118} INFO - Task exited with return code 1
