[2021-02-17 12:13:46,061] {taskinstance.py:826} INFO - Dependencies all met for <TaskInstance: ge_quarantine_df_dag.import_invalid_records 2021-02-17T11:12:35.769034+00:00 [queued]>
[2021-02-17 12:13:46,078] {taskinstance.py:826} INFO - Dependencies all met for <TaskInstance: ge_quarantine_df_dag.import_invalid_records 2021-02-17T11:12:35.769034+00:00 [queued]>
[2021-02-17 12:13:46,079] {taskinstance.py:1017} INFO - 
--------------------------------------------------------------------------------
[2021-02-17 12:13:46,079] {taskinstance.py:1018} INFO - Starting attempt 1 of 1
[2021-02-17 12:13:46,079] {taskinstance.py:1019} INFO - 
--------------------------------------------------------------------------------
[2021-02-17 12:13:46,098] {taskinstance.py:1038} INFO - Executing <Task(SnowflakeOperator): import_invalid_records> on 2021-02-17T11:12:35.769034+00:00
[2021-02-17 12:13:46,105] {standard_task_runner.py:51} INFO - Started process 12373 to run task
[2021-02-17 12:13:46,141] {standard_task_runner.py:75} INFO - Running: ['airflow', 'tasks', 'run', 'ge_quarantine_df_dag', 'import_invalid_records', '2021-02-17T11:12:35.769034+00:00', '--job-id', '513', '--pool', 'default_pool', '--raw', '--subdir', 'DAGS_FOLDER/ge_quarantine_df_dag.py', '--cfg-path', '/var/folders/s2/xy3ssc8j3ks3whp2f_b8708c0000gp/T/tmpxzriqews']
[2021-02-17 12:13:46,146] {standard_task_runner.py:76} INFO - Job 513: Subtask import_invalid_records
[2021-02-17 12:13:46,203] {logging_mixin.py:103} INFO - Running <TaskInstance: ge_quarantine_df_dag.import_invalid_records 2021-02-17T11:12:35.769034+00:00 [running]> on host 1.0.0.127.in-addr.arpa
[2021-02-17 12:13:46,245] {taskinstance.py:1230} INFO - Exporting the following env vars:
AIRFLOW_CTX_DAG_EMAIL=sara@acloudfrontier.com
AIRFLOW_CTX_DAG_OWNER=sara
AIRFLOW_CTX_DAG_ID=ge_quarantine_df_dag
AIRFLOW_CTX_TASK_ID=import_invalid_records
AIRFLOW_CTX_EXECUTION_DATE=2021-02-17T11:12:35.769034+00:00
AIRFLOW_CTX_DAG_RUN_ID=manual__2021-02-17T11:12:35.769034+00:00
[2021-02-17 12:13:46,246] {snowflake.py:119} INFO - Executing: ['insert into  QUARANTINE_DATA select * from RAW_MONTHLY_TAXI where GE_validation_result=1;']
[2021-02-17 12:13:46,255] {base.py:65} INFO - Using connection to: id: SNOWFLAKE_QUARANTINE_DEMO. Host: dp13486.eu-west-1.snowflakecomputing.com, Port: None, Schema: PUBLIC, Login: SARA, Password: XXXXXXXX, extra: XXXXXXXX
[2021-02-17 12:13:46,259] {connection.py:215} INFO - Snowflake Connector for Python Version: 2.3.9, Python Version: 3.8.6, Platform: macOS-10.16-x86_64-i386-64bit
[2021-02-17 12:13:46,260] {connection.py:768} INFO - This connection is in OCSP Fail Open Mode. TLS Certificates would be checked for validity and revocation status. Any other Certificate Revocation related exceptions or OCSP Responder failures would be disregarded in favor of connectivity.
[2021-02-17 12:13:46,261] {connection.py:784} INFO - Setting use_openssl_only mode to False
[2021-02-17 12:13:47,478] {cursor.py:537} INFO - query: [ALTER SESSION SET autocommit=True]
[2021-02-17 12:13:47,586] {cursor.py:560} INFO - query execution done
[2021-02-17 12:13:47,587] {dbapi.py:180} INFO - Running statement: insert into  QUARANTINE_DATA select * from RAW_MONTHLY_TAXI where GE_validation_result=1;, parameters: None
[2021-02-17 12:13:47,588] {cursor.py:537} INFO - query: [insert into  QUARANTINE_DATA select * from RAW_MONTHLY_TAXI where GE_validation_...]
[2021-02-17 12:13:48,290] {cursor.py:560} INFO - query execution done
[2021-02-17 12:13:48,291] {dbapi.py:186} INFO - Rows affected: 1579
[2021-02-17 12:13:48,292] {connection.py:438} INFO - closed
[2021-02-17 12:13:48,363] {connection.py:441} INFO - No async queries seem to be running, deleting session
[2021-02-17 12:13:48,454] {taskinstance.py:1135} INFO - Marking task as SUCCESS. dag_id=ge_quarantine_df_dag, task_id=import_invalid_records, execution_date=20210217T111235, start_date=20210217T111346, end_date=20210217T111348
[2021-02-17 12:13:48,474] {taskinstance.py:1195} INFO - 0 downstream tasks scheduled from follow-on schedule check
[2021-02-17 12:13:48,532] {local_task_job.py:118} INFO - Task exited with return code 0
