[2021-02-03 09:38:33,602] {taskinstance.py:826} INFO - Dependencies all met for <TaskInstance: ge_quarantine_df_dag.import_raw_monthly_data 2021-02-03T08:38:25.665377+00:00 [queued]>
[2021-02-03 09:38:33,614] {taskinstance.py:826} INFO - Dependencies all met for <TaskInstance: ge_quarantine_df_dag.import_raw_monthly_data 2021-02-03T08:38:25.665377+00:00 [queued]>
[2021-02-03 09:38:33,615] {taskinstance.py:1017} INFO - 
--------------------------------------------------------------------------------
[2021-02-03 09:38:33,615] {taskinstance.py:1018} INFO - Starting attempt 1 of 1
[2021-02-03 09:38:33,615] {taskinstance.py:1019} INFO - 
--------------------------------------------------------------------------------
[2021-02-03 09:38:33,627] {taskinstance.py:1038} INFO - Executing <Task(SnowflakeOperator): import_raw_monthly_data> on 2021-02-03T08:38:25.665377+00:00
[2021-02-03 09:38:33,631] {standard_task_runner.py:51} INFO - Started process 15020 to run task
[2021-02-03 09:38:33,642] {standard_task_runner.py:75} INFO - Running: ['airflow', 'tasks', 'run', 'ge_quarantine_df_dag', 'import_raw_monthly_data', '2021-02-03T08:38:25.665377+00:00', '--job-id', '332', '--pool', 'default_pool', '--raw', '--subdir', 'DAGS_FOLDER/ge_quarantine_df_dag.py', '--cfg-path', '/var/folders/s2/xy3ssc8j3ks3whp2f_b8708c0000gp/T/tmpq5o0vsub']
[2021-02-03 09:38:33,645] {standard_task_runner.py:76} INFO - Job 332: Subtask import_raw_monthly_data
[2021-02-03 09:38:33,698] {logging_mixin.py:103} INFO - Running <TaskInstance: ge_quarantine_df_dag.import_raw_monthly_data 2021-02-03T08:38:25.665377+00:00 [running]> on host 1.0.0.127.in-addr.arpa
[2021-02-03 09:38:33,743] {taskinstance.py:1230} INFO - Exporting the following env vars:
AIRFLOW_CTX_DAG_EMAIL=sara@acloudfrontier.com
AIRFLOW_CTX_DAG_OWNER=sara
AIRFLOW_CTX_DAG_ID=ge_quarantine_df_dag
AIRFLOW_CTX_TASK_ID=import_raw_monthly_data
AIRFLOW_CTX_EXECUTION_DATE=2021-02-03T08:38:25.665377+00:00
AIRFLOW_CTX_DAG_RUN_ID=manual__2021-02-03T08:38:25.665377+00:00
[2021-02-03 09:38:33,745] {snowflake.py:119} INFO - Executing: ['put file:////Users/sara/airflow/dags/local/yellow_tripdata_sample_2019-01.csv @%raw_monthly_taxi;', "copy into raw_monthly_taxi from '@%raw_monthly_taxi/yellow_tripdata_sample_2019-01.csv.gz' ;", 'alter table RAW_MONTHLY_TAXI add column error integer;']
[2021-02-03 09:38:33,756] {base.py:65} INFO - Using connection to: id: SNOWFLAKE_QUARANTINE_DEMO. Host: dp13486.eu-west-1.snowflakecomputing.com, Port: None, Schema: PUBLIC, Login: SARA, Password: XXXXXXXX, extra: XXXXXXXX
[2021-02-03 09:38:33,760] {connection.py:215} INFO - Snowflake Connector for Python Version: 2.3.9, Python Version: 3.8.6, Platform: macOS-10.16-x86_64-i386-64bit
[2021-02-03 09:38:33,761] {connection.py:768} INFO - This connection is in OCSP Fail Open Mode. TLS Certificates would be checked for validity and revocation status. Any other Certificate Revocation related exceptions or OCSP Responder failures would be disregarded in favor of connectivity.
[2021-02-03 09:38:33,763] {connection.py:784} INFO - Setting use_openssl_only mode to False
[2021-02-03 09:38:35,193] {cursor.py:537} INFO - query: [ALTER SESSION SET autocommit=True]
[2021-02-03 09:38:35,322] {cursor.py:560} INFO - query execution done
[2021-02-03 09:38:35,324] {dbapi.py:180} INFO - Running statement: put file:////Users/sara/airflow/dags/local/yellow_tripdata_sample_2019-01.csv @%raw_monthly_taxi;, parameters: None
[2021-02-03 09:38:35,326] {cursor.py:537} INFO - query: [put file:////Users/sara/airflow/dags/local/yellow_tripdata_sample_2019-01.csv @%...]
[2021-02-03 09:38:35,827] {cursor.py:560} INFO - query execution done
[2021-02-03 09:38:38,740] {dbapi.py:186} INFO - Rows affected: 1
[2021-02-03 09:38:38,740] {dbapi.py:180} INFO - Running statement: copy into raw_monthly_taxi from '@%raw_monthly_taxi/yellow_tripdata_sample_2019-01.csv.gz' ;, parameters: None
[2021-02-03 09:38:38,742] {cursor.py:537} INFO - query: [copy into raw_monthly_taxi from '@%raw_monthly_taxi/yellow_tripdata_sample_2019-...]
[2021-02-03 09:38:40,650] {cursor.py:560} INFO - query execution done
[2021-02-03 09:38:40,651] {dbapi.py:186} INFO - Rows affected: 1
[2021-02-03 09:38:40,652] {dbapi.py:180} INFO - Running statement: alter table RAW_MONTHLY_TAXI add column error integer;, parameters: None
[2021-02-03 09:38:40,652] {cursor.py:537} INFO - query: [alter table RAW_MONTHLY_TAXI add column error integer;]
[2021-02-03 09:38:40,948] {cursor.py:560} INFO - query execution done
[2021-02-03 09:38:40,949] {dbapi.py:186} INFO - Rows affected: 1
[2021-02-03 09:38:40,951] {connection.py:438} INFO - closed
[2021-02-03 09:38:41,027] {connection.py:441} INFO - No async queries seem to be running, deleting session
[2021-02-03 09:38:41,148] {taskinstance.py:1135} INFO - Marking task as SUCCESS. dag_id=ge_quarantine_df_dag, task_id=import_raw_monthly_data, execution_date=20210203T083825, start_date=20210203T083833, end_date=20210203T083841
[2021-02-03 09:38:41,225] {taskinstance.py:1195} INFO - 1 downstream tasks scheduled from follow-on schedule check
[2021-02-03 09:38:41,255] {local_task_job.py:118} INFO - Task exited with return code 0
